[2025-03-26T02:03:38.096+0000] {local_task_job_runner.py:120} INFO - ::group::Pre task execution logs
[2025-03-26T02:03:38.142+0000] {taskinstance.py:2076} INFO - Dependencies all met for dep_context=non-requeueable deps ti=<TaskInstance: api_to_s3_to_clickhouse.load_into_clickhouse manual__2025-03-26T01:46:27.818259+00:00 [queued]>
[2025-03-26T02:03:38.155+0000] {taskinstance.py:2076} INFO - Dependencies all met for dep_context=requeueable deps ti=<TaskInstance: api_to_s3_to_clickhouse.load_into_clickhouse manual__2025-03-26T01:46:27.818259+00:00 [queued]>
[2025-03-26T02:03:38.155+0000] {taskinstance.py:2306} INFO - Starting attempt 2 of 2
[2025-03-26T02:03:38.182+0000] {taskinstance.py:2330} INFO - Executing <Task(PythonOperator): load_into_clickhouse> on 2025-03-26 01:46:27.818259+00:00
[2025-03-26T02:03:38.198+0000] {standard_task_runner.py:90} INFO - Running: ['***', 'tasks', 'run', 'api_to_s3_to_clickhouse', 'load_into_clickhouse', 'manual__2025-03-26T01:46:27.818259+00:00', '--job-id', '40', '--raw', '--subdir', 'DAGS_FOLDER/extract.py', '--cfg-path', '/tmp/tmpjnjguotc']
[2025-03-26T02:03:38.203+0000] {standard_task_runner.py:91} INFO - Job 40: Subtask load_into_clickhouse
[2025-03-26T02:03:38.205+0000] {logging_mixin.py:188} WARNING - /home/***/.local/lib/python3.12/site-packages/***/task/task_runner/standard_task_runner.py:61 DeprecationWarning: This process (pid=612) is multi-threaded, use of fork() may lead to deadlocks in the child.
[2025-03-26T02:03:38.207+0000] {standard_task_runner.py:63} INFO - Started process 625 to run task
[2025-03-26T02:03:38.282+0000] {task_command.py:426} INFO - Running <TaskInstance: api_to_s3_to_clickhouse.load_into_clickhouse manual__2025-03-26T01:46:27.818259+00:00 [running]> on host 7ea2041f8442
[2025-03-26T02:03:38.419+0000] {taskinstance.py:2648} INFO - Exporting env vars: AIRFLOW_CTX_DAG_OWNER='***' AIRFLOW_CTX_DAG_ID='api_to_s3_to_clickhouse' AIRFLOW_CTX_TASK_ID='load_into_clickhouse' AIRFLOW_CTX_EXECUTION_DATE='2025-03-26T01:46:27.818259+00:00' AIRFLOW_CTX_TRY_NUMBER='2' AIRFLOW_CTX_DAG_RUN_ID='manual__2025-03-26T01:46:27.818259+00:00'
[2025-03-26T02:03:38.420+0000] {taskinstance.py:430} INFO - ::endgroup::
[2025-03-26T02:03:38.502+0000] {credentials.py:1147} INFO - Found credentials in environment variables.
[2025-03-26T02:03:41.477+0000] {logging_mixin.py:188} INFO - âœ… Downloaded from S3: /tmp/all_college_data.json
[2025-03-26T02:03:41.573+0000] {taskinstance.py:441} INFO - ::group::Post task execution logs
[2025-03-26T02:03:41.574+0000] {taskinstance.py:2905} ERROR - Task failed with exception
Traceback (most recent call last):
  File "/home/airflow/.local/lib/python3.12/site-packages/airflow/models/taskinstance.py", line 465, in _execute_task
    result = _execute_callable(context=context, **execute_callable_kwargs)
             ^^^^^^^^^^^^^^^^^^^^^^^^^^^^^^^^^^^^^^^^^^^^^^^^^^^^^^^^^^^^^
  File "/home/airflow/.local/lib/python3.12/site-packages/airflow/models/taskinstance.py", line 432, in _execute_callable
    return execute_callable(context=context, **execute_callable_kwargs)
           ^^^^^^^^^^^^^^^^^^^^^^^^^^^^^^^^^^^^^^^^^^^^^^^^^^^^^^^^^^^^
  File "/home/airflow/.local/lib/python3.12/site-packages/airflow/models/baseoperator.py", line 401, in wrapper
    return func(self, *args, **kwargs)
           ^^^^^^^^^^^^^^^^^^^^^^^^^^^
  File "/home/airflow/.local/lib/python3.12/site-packages/airflow/operators/python.py", line 235, in execute
    return_value = self.execute_callable()
                   ^^^^^^^^^^^^^^^^^^^^^^^
  File "/home/airflow/.local/lib/python3.12/site-packages/airflow/operators/python.py", line 252, in execute_callable
    return self.python_callable(*self.op_args, **self.op_kwargs)
           ^^^^^^^^^^^^^^^^^^^^^^^^^^^^^^^^^^^^^^^^^^^^^^^^^^^^^
  File "/opt/airflow/dags/extract.py", line 158, in load_into_clickhouse
    client.insert("college_data", formatted_data, column_names=column_names)
  File "/home/airflow/.local/lib/python3.12/site-packages/clickhouse_connect/driver/client.py", line 624, in insert
    context = self.create_insert_context(table,
              ^^^^^^^^^^^^^^^^^^^^^^^^^^^^^^^^^
  File "/home/airflow/.local/lib/python3.12/site-packages/clickhouse_connect/driver/client.py", line 741, in create_insert_context
    raise ProgrammingError(f'Unrecognized column {ex} in table {table}') from None
clickhouse_connect.driver.exceptions.ProgrammingError: Unrecognized column 'school_name' in table college_data
[2025-03-26T02:03:41.588+0000] {taskinstance.py:1206} INFO - Marking task as FAILED. dag_id=api_to_s3_to_clickhouse, task_id=load_into_clickhouse, run_id=manual__2025-03-26T01:46:27.818259+00:00, execution_date=20250326T014627, start_date=20250326T020338, end_date=20250326T020341
[2025-03-26T02:03:41.607+0000] {standard_task_runner.py:110} ERROR - Failed to execute job 40 for task load_into_clickhouse (Unrecognized column 'school_name' in table college_data; 625)
[2025-03-26T02:03:41.635+0000] {local_task_job_runner.py:240} INFO - Task exited with return code 1
[2025-03-26T02:03:41.656+0000] {taskinstance.py:3503} INFO - 0 downstream tasks scheduled from follow-on schedule check
[2025-03-26T02:03:41.662+0000] {local_task_job_runner.py:222} INFO - ::endgroup::
